Workbook

Sheet Invullen groen
A1: Invullen groen — Begrotingswijziging
A2: =A4 | L2: =IFERROR('Invullen groen'!L4,"")
A4: Begrotingswijziging 2026 | G4: Nummer wijziging:
A5: Omschrijving wijziging:
A6: Programma / afdeling: | G6: Corsanummer wijziging: | Q6: Controle budgettair neutrale categorieen
G7: Corsanummer raadsvoorstel:
Q8: Nummer wijziging:
A11: A. Mutaties in de inkomsten en uitgaven (raming van baten en lasten) | H11: -/- = baten
A13: Programma | B13: Nr.hoofd- taakveld | C13: Nr. taakveld | D13: Omschrijving taakveld | E13: Nr grootboek | F13: Econ. categorie | G13: Omschrijving grootboek | H13: Bgr.jaar | I13: MJR | J13: MJR | K13: MJR | L13: Bgr w | M13: Omschr. kostencat. | N13: Nr verbijz- | O13: Omschrijving | Q13: Lasten | R13: Baten
F14: nr | H14: 2026 | I14: 2027 | J14: 2028 | K14: 2029 | N14: ondering | O14: verbijzondering | Q14: 47100 / 47200 | R14: 87100 / 87201
Q15: 47201 / 47500 | R15: 87201 / 87500
A16: A. Uitgaven en inkomsten | Q16: → alleen directe lasten en baten; reserves/voorzieningen in sectie B
A17: =IFERROR(VLOOKUP(E17,Tabellen!A:F,4),0) | C17: =IFERROR(VLOOKUP(E17,Tabellen!A:F,5),0) | D17: =IFERROR(VLOOKUP(E17,Tabellen!A:F,6),0) | G17: =IFERROR(VLOOKUP(E17,Tabellen!A:F,2),0) | L17: =IF(E17>0,$H$4,0) | M17: =IFERROR(VLOOKUP(F17,Tabellen!H:I,2),0) | P17: =IF(E17>0,COUNTIF($E$17:E17,">0"),0) | Q17: =IF(OR(F17=47201,F17=47100,F17=47200,F17=47500),H17,0) | R17: =IF(OR(F17=87201,F17=87100,F17=87200,F17=87500),H17,0)
A18: =IFERROR(VLOOKUP(E18,Tabellen!A:F,4),0) | C18: =IFERROR(VLOOKUP(E18,Tabellen!A:F,5),0) | D18: =IFERROR(VLOOKUP(E18,Tabellen!A:F,6),0) | G18: =IFERROR(VLOOKUP(E18,Tabellen!A:F,2),0) | L18: =IF(E18>0,$H$4,0) | M18: =IFERROR(VLOOKUP(F18,Tabellen!H:I,2),0) | P18: =IF(E18>0,COUNTIF($E$17:E18,">0"),0) | Q18: =IF(OR(F18=47201,F18=47100,F18=47200,F18=47500),H18,0) | R18: =IF(OR(F18=87201,F18=87100,F18=87200,F18=87500),H18,0)
A19: =IFERROR(VLOOKUP(E19,Tabellen!A:F,4),0) | C19: =IFERROR(VLOOKUP(E19,Tabellen!A:F,5),0) | D19: =IFERROR(VLOOKUP(E19,Tabellen!A:F,6),0) | F19: =IFERROR(VLOOKUP(E19,Tabellen!A:H,8),0) | G19: =IFERROR(VLOOKUP(E19,Tabellen!A:F,2),0) | L19: =IF(E19>0,$H$4,0) | M19: =IFERROR(VLOOKUP(F19,Tabellen!H:I,2),0) | P19: =IF(E19>0,COUNTIF($E$17:E19,">0"),0) | Q19: =IF(OR(F19=47201,F19=47100,F19=47200,F19=47500),H19,0) | R19: =IF(OR(F19=87201,F19=87100,F19=87200,F19=87500),H19,0)
A20: =IFERROR(VLOOKUP(E20,Tabellen!A:F,4),0) | C20: =IFERROR(VLOOKUP(E20,Tabellen!A:F,5),0) | D20: =IFERROR(VLOOKUP(E20,Tabellen!A:F,6),0) | F20: =IFERROR(VLOOKUP(E20,Tabellen!A:H,8),0) | G20: =IFERROR(VLOOKUP(E20,Tabellen!A:F,2),0) | L20: =IF(E20>0,$H$4,0) | M20: =IFERROR(VLOOKUP(F20,Tabellen!H:I,2),0) | P20: =IF(E20>0,COUNTIF($E$17:E20,">0"),0) | Q20: =IF(OR(F20=47201,F20=47100,F20=47200,F20=47500),H20,0) | R20: =IF(OR(F20=87201,F20=87100,F20=87200,F20=87500),H20,0)
A21: =IFERROR(VLOOKUP(E21,Tabellen!A:F,4),0) | C21: =IFERROR(VLOOKUP(E21,Tabellen!A:F,5),0) | D21: =IFERROR(VLOOKUP(E21,Tabellen!A:F,6),0) | F21: =IFERROR(VLOOKUP(E21,Tabellen!A:H,8),0) | G21: =IFERROR(VLOOKUP(E21,Tabellen!A:F,2),0) | L21: =IF(E21>0,$H$4,0) | M21: =IFERROR(VLOOKUP(F21,Tabellen!H:I,2),0) | P21: =IF(E21>0,COUNTIF($E$17:E21,">0"),0) | Q21: =IF(OR(F21=47201,F21=47100,F21=47200,F21=47500),H21,0) | R21: =IF(OR(F21=87201,F21=87100,F21=87200,F21=87500),H21,0)
A22: =IFERROR(VLOOKUP(E22,Tabellen!A:F,4),0) | C22: =IFERROR(VLOOKUP(E22,Tabellen!A:F,5),0) | D22: =IFERROR(VLOOKUP(E22,Tabellen!A:F,6),0) | F22: =IFERROR(VLOOKUP(E22,Tabellen!A:H,8),0) | G22: =IFERROR(VLOOKUP(E22,Tabellen!A:F,2),0) | L22: =IF(E22>0,$H$4,0) | M22: =IFERROR(VLOOKUP(F22,Tabellen!H:I,2),0) | P22: =IF(E22>0,COUNTIF($E$17:E22,">0"),0) | Q22: =IF(OR(F22=47201,F22=47100,F22=47200,F22=47500),H22,0) | R22: =IF(OR(F22=87201,F22=87100,F22=87200,F22=87500),H22,0)
A23: =IFERROR(VLOOKUP(E23,Tabellen!A:F,4),0) | C23: =IFERROR(VLOOKUP(E23,Tabellen!A:F,5),0) | D23: =IFERROR(VLOOKUP(E23,Tabellen!A:F,6),0) | F23: =IFERROR(VLOOKUP(E23,Tabellen!A:H,8),0) | G23: =IFERROR(VLOOKUP(E23,Tabellen!A:F,2),0) | L23: =IF(E23>0,$H$4,0) | M23: =IFERROR(VLOOKUP(F23,Tabellen!H:I,2),0) | P23: =IF(E23>0,COUNTIF($E$17:E23,">0"),0) | Q23: =IF(OR(F23=47201,F23=47100,F23=47200,F23=47500),H23,0) | R23: =IF(OR(F23=87201,F23=87100,F23=87200,F23=87500),H23,0)
A24: =IFERROR(VLOOKUP(E24,Tabellen!A:F,4),0) | C24: =IFERROR(VLOOKUP(E24,Tabellen!A:F,5),0) | D24: =IFERROR(VLOOKUP(E24,Tabellen!A:F,6),0) | F24: =IFERROR(VLOOKUP(E24,Tabellen!A:H,8),0) | G24: =IFERROR(VLOOKUP(E24,Tabellen!A:F,2),0) | L24: =IF(E24>0,$H$4,0) | M24: =IFERROR(VLOOKUP(F24,Tabellen!H:I,2),0) | P24: =IF(E24>0,COUNTIF($E$17:E24,">0"),0) | Q24: =IF(OR(F24=47201,F24=47100,F24=47200,F24=47500),H24,0) | R24: =IF(OR(F24=87201,F24=87100,F24=87200,F24=87500),H24,0)
A25: =IFERROR(VLOOKUP(E25,Tabellen!A:F,4),0) | C25: =IFERROR(VLOOKUP(E25,Tabellen!A:F,5),0) | D25: =IFERROR(VLOOKUP(E25,Tabellen!A:F,6),0) | F25: =IFERROR(VLOOKUP(E25,Tabellen!A:H,8),0) | G25: =IFERROR(VLOOKUP(E25,Tabellen!A:F,2),0) | L25: =IF(E25>0,$H$4,0) | M25: =IFERROR(VLOOKUP(F25,Tabellen!H:I,2),0) | P25: =IF(E25>0,COUNTIF($E$17:E25,">0"),0) | Q25: =IF(OR(F25=47201,F25=47100,F25=47200,F25=47500),H25,0) | R25: =IF(OR(F25=87201,F25=87100,F25=87200,F25=87500),H25,0)
A26: =IFERROR(VLOOKUP(E26,Tabellen!A:F,4),0) | C26: =IFERROR(VLOOKUP(E26,Tabellen!A:F,5),0) | D26: =IFERROR(VLOOKUP(E26,Tabellen!A:F,6),0) | F26: =IFERROR(VLOOKUP(E26,Tabellen!A:H,8),0) | G26: =IFERROR(VLOOKUP(E26,Tabellen!A:F,2),0) | L26: =IF(E26>0,$H$4,0) | M26: =IFERROR(VLOOKUP(F26,Tabellen!H:I,2),0) | P26: =IF(E26>0,COUNTIF($E$17:E26,">0"),0) | Q26: =IF(OR(F26=47201,F26=47100,F26=47200,F26=47500),H26,0) | R26: =IF(OR(F26=87201,F26=87100,F26=87200,F26=87500),H26,0)
A27: =IFERROR(VLOOKUP(E27,Tabellen!A:F,4),0) | C27: =IFERROR(VLOOKUP(E27,Tabellen!A:F,5),0) | D27: =IFERROR(VLOOKUP(E27,Tabellen!A:F,6),0) | F27: =IFERROR(VLOOKUP(E27,Tabellen!A:H,8),0) | G27: =IFERROR(VLOOKUP(E27,Tabellen!A:F,2),0) | L27: =IF(E27>0,$H$4,0) | M27: =IFERROR(VLOOKUP(F27,Tabellen!H:I,2),0) | P27: =IF(E27>0,COUNTIF($E$17:E27,">0"),0) | Q27: =IF(OR(F27=47201,F27=47100,F27=47200,F27=47500),H27,0) | R27: =IF(OR(F27=87201,F27=87100,F27=87200,F27=87500),H27,0)
A28: =IFERROR(VLOOKUP(E28,Tabellen!A:F,4),0) | C28: =IFERROR(VLOOKUP(E28,Tabellen!A:F,5),0) | D28: =IFERROR(VLOOKUP(E28,Tabellen!A:F,6),0) | F28: =IFERROR(VLOOKUP(E28,Tabellen!A:H,8),0) | G28: =IFERROR(VLOOKUP(E28,Tabellen!A:F,2),0) | L28: =IF(E28>0,$H$4,0) | M28: =IFERROR(VLOOKUP(F28,Tabellen!H:I,2),0) | P28: =IF(E28>0,COUNTIF($E$17:E28,">0"),0) | Q28: =IF(OR(F28=47201,F28=47100,F28=47200,F28=47500),H28,0) | R28: =IF(OR(F28=87201,F28=87100,F28=87200,F28=87500),H28,0)
A29: =IFERROR(VLOOKUP(E29,Tabellen!A:F,4),0) | C29: =IFERROR(VLOOKUP(E29,Tabellen!A:F,5),0) | D29: =IFERROR(VLOOKUP(E29,Tabellen!A:F,6),0) | F29: =IFERROR(VLOOKUP(E29,Tabellen!A:H,8),0) | G29: =IFERROR(VLOOKUP(E29,Tabellen!A:F,2),0) | L29: =IF(E29>0,$H$4,0) | M29: =IFERROR(VLOOKUP(F29,Tabellen!H:I,2),0) | P29: =IF(E29>0,COUNTIF($E$17:E29,">0"),0) | Q29: =IF(OR(F29=47201,F29=47100,F29=47200,F29=47500),H29,0) | R29: =IF(OR(F29=87201,F29=87100,F29=87200,F29=87500),H29,0)
A30: =IFERROR(VLOOKUP(E30,Tabellen!A:F,4),0) | C30: =IFERROR(VLOOKUP(E30,Tabellen!A:F,5),0) | D30: =IFERROR(VLOOKUP(E30,Tabellen!A:F,6),0) | F30: =IFERROR(VLOOKUP(E30,Tabellen!A:H,8),0) | G30: =IFERROR(VLOOKUP(E30,Tabellen!A:F,2),0) | L30: =IF(E30>0,$H$4,0) | M30: =IFERROR(VLOOKUP(F30,Tabellen!H:I,2),0) | P30: =IF(E30>0,COUNTIF($E$17:E30,">0"),0) | Q30: =IF(OR(F30=47201,F30=47100,F30=47200,F30=47500),H30,0) | R30: =IF(OR(F30=87201,F30=87100,F30=87200,F30=87500),H30,0)
... A74: =IFERROR(VLOOKUP(E74,Tabellen!A:F,4),0) | C74: =IFERROR(VLOOKUP(E74,Tabellen!A:F,5),0) | D74: =IFERROR(VLOOKUP(E74,Tabellen!A:F,6),0) | F74: =IFERROR(VLOOKUP(E74,Tabellen!A:H,8),0) | G74: =IFERROR(VLOOKUP(E74,Tabellen!A:F,2),0) | L74: =IF(E74>0,$H$4,0) | M74: =IFERROR(VLOOKUP(F74,Tabellen!H:I,2),0) | P74: =IF(E74>0,COUNTIF($E$17:E74,">0"),0) | Q74: =IF(OR(F74=47201,F74=47100,F74=47200,F74=47500),H74,0) | R74: =IF(OR(F74=87201,F74=87100,F74=87200,F74=87500),H74,0)
A75: Saldo inkomsten en uitgaven | H75: =SUM(H17:H74) | I75: =SUM(I17:I74) | J75: =SUM(J17:J74) | K75: =SUM(K17:K74) | P75: =IF(E75>0,COUNTIF($E$17:E75,">0"),0) | Q75: =IF(OR(F75=47201,F75=47100,F75=47200,F75=47500),H75,0) | R75: =IF(OR(F75=87201,F75=87100,F75=87200,F75=87500),H75,0)
A112: Controle mutatie inkomsten en uitgaven (exploitatiemutaties -/- dekking = leeg) | H112: =IF(H75=0,"✓ Saldo = 0",TEXT(H75,"#.##0")) | I112: =IF(I75=0,"✓ Saldo = 0",TEXT(I75,"#.##0")) | J112: =IF(J75=0,"✓ Saldo = 0",TEXT(J75,"#.##0")) | K112: =IF(K75=0,"✓ Saldo = 0",TEXT(K75,"#.##0")) | P112: =IF(E112>0,COUNTIF($E$17:E112,">0"),0) | Q112: =IF(OR(L112=47201,L112=47100,L112=47200,L112=47500),H112,0) | R112: =IF(OR(L112=87201,L112=87100,L112=87200,L112=87500),H112,0)
P113: =IF(E113>0,COUNTIF($E$17:E113,">0"),0) | Q113: =IF(OR(L113=47201,L113=47100,L113=47200,L113=47500),H113,0) | R113: =IF(OR(L113=87201,L113=87100,L113=87200,L113=87500),H113,0)
P114: =IF(E114>0,COUNTIF($E$17:E114,">0"),0) | Q114: =IF(OR(L114=47201,L114=47100,L114=47200,L114=47500),H114,0) | R114: =IF(OR(L114=87201,L114=87100,L114=87200,L114=87500),H114,0)
A115: Mutaties in de balans (investerings- en financieringsstaat) | P115: =IF(E115>0,COUNTIF($E$17:E115,">0"),0) | Q115: =IF(OR(L115=47201,L115=47100,L115=47200,L115=47500),H115,0) | R115: =IF(OR(L115=87201,L115=87100,L115=87200,L115=87500),H115,0)
P116: =IF(E116>0,COUNTIF($E$17:E116,">0"),0) | Q116: =IF(OR(L116=47201,L116=47100,L116=47200,L116=47500),H116,0) | R116: =IF(OR(L116=87201,L116=87100,L116=87200,L116=87500),H116,0)
A117: Omschrijving balanspost | B117: nvt | C117: nvt | D117: nvt | G117: Omschrijving boeking | H117: Bgr.jaar | I117: MJR | J117: MJR | K117: MJR | L117: Kosten | M117: Omschrijving kostencategorie | N117: Nr ver- | O117: Omschrijving | P117: =IF(E117>0,COUNTIF($E$17:E117,">0"),0) | Q117: =IF(OR(L117=47201,L117=47100,L117=47200,L117=47500),H117,0) | R117: =IF(OR(L117=87201,L117=87100,L117=87200,L117=87500),H117,0)
H118: 2026 | I118: 2027 | J118: 2028 | K118: 2029 | L118: Cat | N118: bijzondering | O118: verbijzondering | P118: =IF(E118>0,COUNTIF($E$17:E118,">0"),0) | Q118: =IF(OR(L118=47201,L118=47100,L118=47200,L118=47500),H118,0) | R118: =IF(OR(L118=87201,L118=87100,L118=87200,L118=87500),H118,0)
P119: =IF(E119>0,COUNTIF($E$17:E119,">0"),0) | Q119: =IF(OR(L119=47201,L119=47100,L119=47200,L119=47500),H119,0) | R119: =IF(OR(L119=87201,L119=87100,L119=87200,L119=87500),H119,0)
A120: B. Investeringen | P120: =IF(E120>0,COUNTIF($E$17:E120,">0"),0) | Q120: =IF(OR(L120=47201,L120=47100,L120=47200,L120=47500),H120,0) | R120: =IF(OR(L120=87201,L120=87100,L120=87200,L120=87500),H120,0)
P121: =IF(E121>0,COUNTIF($E$17:E121,">0"),0) | Q121: =IF(OR(F121=47201,F121=47100,F121=47200,F121=47500),H121,0) | R121: =IF(OR(F121=87201,F121=87100,F121=87200,F121=87500),H121,0) | S121: =IF(E121>0,COUNTIF($E$121:E121,">0"),0)
A122: Activa | L122: =IF(E122>0,$H$4,0) | M122: =IFERROR(VLOOKUP(F122,Tabellen!H:I,2),0) | P122: =IF(E122>0,COUNTIF($E$17:E122,">0"),0) | Q122: =IF(OR(F122=47201,F122=47100,F122=47200,F122=47500),H122,0) | R122: =IF(OR(F122=87201,F122=87100,F122=87200,F122=87500),H122,0) | S122: =IF(E122>0,COUNTIF($E$121:E122,">0"),0)
L123: =IF(E123>0,$H$4,0) | M123: =IFERROR(VLOOKUP(F123,Tabellen!H:I,2),0) | P123: =IF(E123>0,COUNTIF($E$17:E123,">0"),0) | Q123: =IF(OR(F123=47201,F123=47100,F123=47200,F123=47500),H123,0) | R123: =IF(OR(F123=87201,F123=87100,F123=87200,F123=87500),H123,0) | S123: =IF(E123>0,COUNTIF($E$121:E123,">0"),0)
...

Sheet Administratieve wijz en Coda
A1: Coda import — Begrotingswijziging | C1: ='Invullen groen'!H4 | K1: ='Invullen groen'!H4
F2: Baten en lasten: | G2: Baten en lasten: | H2: Baten en lasten: | I2: Baten en lasten:
F3: 2026 | G3: 2027 | H3: 2028 | I3: 2029
A4: Grootboek | B4: Econ.Categorie | C4: Verbijzondering | D4: Verdere verbijz. | E4: Omschrijving | F4: Bedrag: | G4: Bedrag: | H4: Bedrag: | I4: Bedrag:
A5: =IFERROR(IF($L5>0,INDEX('Invullen groen'!$E:$E,$L5),""),"") | B5: =IFERROR(IF($L5>0,IF(INDEX('Invullen groen'!$F:$F,$L5)>0,INDEX('Invullen groen'!$F:$F,$L5),""),""),"") | C5: =IFERROR(IF($L5>0,IF(INDEX('Invullen groen'!$N:$N,$L5)>0,INDEX('Invullen groen'!$N:$N,$L5),""),""),"") | E5: =IFERROR(IF(LEN(J5)<=36,J5,IFERROR(LEFT(J5,FIND(CHAR(1),SUBSTITUTE(LEFT(J5,36)," ",CHAR(1),LEN(LEFT(J5,36))-LEN(SUBSTITUTE(LEFT(J5,36)," ",""))))-1),LEFT(O5,36))),"") | F5: =IFERROR(IF($L5>0,IF(INDEX('Invullen groen'!$H:$H,$L5)=0,"",INT(INDEX('Invullen groen'!$H:$H,$L5))),""),"") | G5: =IFERROR(IF($L5>0,IF(INDEX('Invullen groen'!$I:$I,$L5)=0,"",INT(INDEX('Invullen groen'!$I:$I,$L5))),""),"") | H5: =IFERROR(IF($L5>0,IF(INDEX('Invullen groen'!$J:$J,$L5)=0,"",INT(INDEX('Invullen groen'!$J:$J,$L5))),""),"") | I5: =IFERROR(IF($L5>0,IF(INDEX('Invullen groen'!$K:$K,$L5)=0,"",INT(INDEX('Invullen groen'!$K:$K,$L5))),""),"") | J5: =IF($L5>0,IFERROR($K$1&" "&TRIM(SUBSTITUTE(SUBSTITUTE(SUBSTITUTE(SUBSTITUTE(SUBSTITUTE(SUBSTITUTE(SUBSTITUTE(SUBSTITUTE(SUBSTITUTE(SUBSTITUTE(SUBSTITUTE(SUBSTITUTE(LOWER(INDEX('Invullen groen'!$O:$O,$L5)),"2024",""),"2025",""),"2026",""),"2027",""),"2028",""),"2029",""),"taakveld ",""),"installaties","inst"),"ruwbouw","ruwb"),"afbouw","afb"),"bijstelling","bijst"),"investeringen","invest")),""),"") | L5: =IFERROR(MATCH(ROW()-4,'Invullen groen'!$P$17:$P$109,0)+16,0)
A6: =IFERROR(IF($L6>0,INDEX('Invullen groen'!$E:$E,$L6),""),"") | B6: =IFERROR(IF($L6>0,IF(INDEX('Invullen groen'!$F:$F,$L6)>0,INDEX('Invullen groen'!$F:$F,$L6),""),""),"") | C6: =IFERROR(IF($L6>0,IF(INDEX('Invullen groen'!$N:$N,$L6)>0,INDEX('Invullen groen'!$N:$N,$L6),""),""),"") | E6: =IFERROR(IF(LEN(J6)<=36,J6,IFERROR(LEFT(J6,FIND(CHAR(1),SUBSTITUTE(LEFT(J6,36)," ",CHAR(1),LEN(LEFT(J6,36))-LEN(SUBSTITUTE(LEFT(J6,36)," ",""))))-1),LEFT(J6,36))),"") | F6: =IFERROR(IF($L6>0,IF(INDEX('Invullen groen'!$H:$H,$L6)=0,"",INT(INDEX('Invullen groen'!$H:$H,$L6))),""),"") | G6: =IFERROR(IF($L6>0,IF(INDEX('Invullen groen'!$I:$I,$L6)=0,"",INT(INDEX('Invullen groen'!$I:$I,$L6))),""),"") | H6: =IFERROR(IF($L6>0,IF(INDEX('Invullen groen'!$J:$J,$L6)=0,"",INT(INDEX('Invullen groen'!$J:$J,$L6))),""),"") | I6: =IFERROR(IF($L6>0,IF(INDEX('Invullen groen'!$K:$K,$L6)=0,"",INT(INDEX('Invullen groen'!$K:$K,$L6))),""),"") | J6: =IF($L6>0,IFERROR($K$1&" "&TRIM(SUBSTITUTE(SUBSTITUTE(SUBSTITUTE(SUBSTITUTE(SUBSTITUTE(SUBSTITUTE(SUBSTITUTE(SUBSTITUTE(SUBSTITUTE(SUBSTITUTE(SUBSTITUTE(SUBSTITUTE(LOWER(INDEX('Invullen groen'!$O:$O,$L6)),"2024",""),"2025",""),"2026",""),"2027",""),"2028",""),"2029",""),"taakveld ",""),"installaties","inst"),"ruwbouw","ruwb"),"afbouw","afb"),"bijstelling","bijst"),"investeringen","invest")),""),"") | L6: =IFERROR(MATCH(ROW()-4,'Invullen groen'!$P$17:$P$109,0)+16,0)
A7: =IFERROR(IF($L7>0,INDEX('Invullen groen'!$E:$E,$L7),""),"") | B7: =IFERROR(IF($L7>0,IF(INDEX('Invullen groen'!$F:$F,$L7)>0,INDEX('Invullen groen'!$F:$F,$L7),""),""),"") | C7: =IFERROR(IF($L7>0,IF(INDEX('Invullen groen'!$N:$N,$L7)>0,INDEX('Invullen groen'!$N:$N,$L7),""),""),"") | E7: =IFERROR(IF(LEN(J7)<=36,J7,IFERROR(LEFT(J7,FIND(CHAR(1),SUBSTITUTE(LEFT(J7,36)," ",CHAR(1),LEN(LEFT(J7,36))-LEN(SUBSTITUTE(LEFT(J7,36)," ",""))))-1),LEFT(J7,36))),"") | F7: =IFERROR(IF($L7>0,IF(INDEX('Invullen groen'!$H:$H,$L7)=0,"",INT(INDEX('Invullen groen'!$H:$H,$L7))),""),"") | G7: =IFERROR(IF($L7>0,IF(INDEX('Invullen groen'!$I:$I,$L7)=0,"",INT(INDEX('Invullen groen'!$I:$I,$L7))),""),"") | H7: =IFERROR(IF($L7>0,IF(INDEX('Invullen groen'!$J:$J,$L7)=0,"",INT(INDEX('Invullen groen'!$J:$J,$L7))),""),"") | I7: =IFERROR(IF($L7>0,IF(INDEX('Invullen groen'!$K:$K,$L7)=0,"",INT(INDEX('Invullen groen'!$K:$K,$L7))),""),"") | J7: =IF($L7>0,IFERROR($K$1&" "&TRIM(SUBSTITUTE(SUBSTITUTE(SUBSTITUTE(SUBSTITUTE(SUBSTITUTE(SUBSTITUTE(SUBSTITUTE(SUBSTITUTE(SUBSTITUTE(SUBSTITUTE(SUBSTITUTE(SUBSTITUTE(LOWER(INDEX('Invullen groen'!$O:$O,$L7)),"2024",""),"2025",""),"2026",""),"2027",""),"2028",""),"2029",""),"taakveld ",""),"installaties","inst"),"ruwbouw","ruwb"),"afbouw","afb"),"bijstelling","bijst"),"investeringen","invest")),""),"") | L7: =IFERROR(MATCH(ROW()-4,'Invullen groen'!$P$17:$P$109,0)+16,0)
A8: =IFERROR(IF($L8>0,INDEX('Invullen groen'!$E:$E,$L8),""),"") | B8: =IFERROR(IF($L8>0,IF(INDEX('Invullen groen'!$F:$F,$L8)>0,INDEX('Invullen groen'!$F:$F,$L8),""),""),"") | C8: =IFERROR(IF($L8>0,IF(INDEX('Invullen groen'!$N:$N,$L8)>0,INDEX('Invullen groen'!$N:$N,$L8),""),""),"") | E8: =IFERROR(IF(LEN(J8)<=36,J8,IFERROR(LEFT(J8,FIND(CHAR(1),SUBSTITUTE(LEFT(J8,36)," ",CHAR(1),LEN(LEFT(J8,36))-LEN(SUBSTITUTE(LEFT(J8,36)," ",""))))-1),LEFT(J8,36))),"") | F8: =IFERROR(IF($L8>0,IF(INDEX('Invullen groen'!$H:$H,$L8)=0,"",INT(INDEX('Invullen groen'!$H:$H,$L8))),""),"") | G8: =IFERROR(IF($L8>0,IF(INDEX('Invullen groen'!$I:$I,$L8)=0,"",INT(INDEX('Invullen groen'!$I:$I,$L8))),""),"") | H8: =IFERROR(IF($L8>0,IF(INDEX('Invullen groen'!$J:$J,$L8)=0,"",INT(INDEX('Invullen groen'!$J:$J,$L8))),""),"") | I8: =IFERROR(IF($L8>0,IF(INDEX('Invullen groen'!$K:$K,$L8)=0,"",INT(INDEX('Invullen groen'!$K:$K,$L8))),""),"") | J8: =IF($L8>0,IFERROR($K$1&" "&TRIM(SUBSTITUTE(SUBSTITUTE(SUBSTITUTE(SUBSTITUTE(SUBSTITUTE(SUBSTITUTE(SUBSTITUTE(SUBSTITUTE(SUBSTITUTE(SUBSTITUTE(SUBSTITUTE(SUBSTITUTE(LOWER(INDEX('Invullen groen'!$O:$O,$L8)),"2024",""),"2025",""),"2026",""),"2027",""),"2028",""),"2029",""),"taakveld ",""),"installaties","inst"),"ruwbouw","ruwb"),"afbouw","afb"),"bijstelling","bijst"),"investeringen","invest")),""),"") | L8: =IFERROR(MATCH(ROW()-4,'Invullen groen'!$P$17:$P$109,0)+16,0)
A9: =IFERROR(IF($L9>0,INDEX('Invullen groen'!$E:$E,$L9),""),"") | B9: =IFERROR(IF($L9>0,IF(INDEX('Invullen groen'!$F:$F,$L9)>0,INDEX('Invullen groen'!$F:$F,$L9),""),""),"") | C9: =IFERROR(IF($L9>0,IF(INDEX('Invullen groen'!$N:$N,$L9)>0,INDEX('Invullen groen'!$N:$N,$L9),""),""),"") | E9: =IFERROR(IF(LEN(J9)<=36,J9,IFERROR(LEFT(J9,FIND(CHAR(1),SUBSTITUTE(LEFT(J9,36)," ",CHAR(1),LEN(LEFT(J9,36))-LEN(SUBSTITUTE(LEFT(J9,36)," ",""))))-1),LEFT(J9,36))),"") | F9: =IFERROR(IF($L9>0,IF(INDEX('Invullen groen'!$H:$H,$L9)=0,"",INT(INDEX('Invullen groen'!$H:$H,$L9))),""),"") | G9: =IFERROR(IF($L9>0,IF(INDEX('Invullen groen'!$I:$I,$L9)=0,"",INT(INDEX('Invullen groen'!$I:$I,$L9))),""),"") | H9: =IFERROR(IF($L9>0,IF(INDEX('Invullen groen'!$J:$J,$L9)=0,"",INT(INDEX('Invullen groen'!$J:$J,$L9))),""),"") | I9: =IFERROR(IF($L9>0,IF(INDEX('Invullen groen'!$K:$K,$L9)=0,"",INT(INDEX('Invullen groen'!$K:$K,$L9))),""),"") | J9: =IF($L9>0,IFERROR($K$1&" "&TRIM(SUBSTITUTE(SUBSTITUTE(SUBSTITUTE(SUBSTITUTE(SUBSTITUTE(SUBSTITUTE(SUBSTITUTE(SUBSTITUTE(SUBSTITUTE(SUBSTITUTE(SUBSTITUTE(SUBSTITUTE(LOWER(INDEX('Invullen groen'!$O:$O,$L9)),"2024",""),"2025",""),"2026",""),"2027",""),"2028",""),"2029",""),"taakveld ",""),"installaties","inst"),"ruwbouw","ruwb"),"afbouw","afb"),"bijstelling","bijst"),"investeringen","invest")),""),"") | L9: =IFERROR(MATCH(ROW()-4,'Invullen groen'!$P$17:$P$109,0)+16,0)
A10: =IFERROR(IF($L10>0,INDEX('Invullen groen'!$E:$E,$L10),""),"") | B10: =IFERROR(IF($L10>0,IF(INDEX('Invullen groen'!$F:$F,$L10)>0,INDEX('Invullen groen'!$F:$F,$L10),""),""),"") | C10: =IFERROR(IF($L10>0,IF(INDEX('Invullen groen'!$N:$N,$L10)>0,INDEX('Invullen groen'!$N:$N,$L10),""),""),"") | E10: =IFERROR(IF(LEN(J10)<=36,J10,IFERROR(LEFT(J10,FIND(CHAR(1),SUBSTITUTE(LEFT(J10,36)," ",CHAR(1),LEN(LEFT(J10,36))-LEN(SUBSTITUTE(LEFT(J10,36)," ",""))))-1),LEFT(J10,36))),"") | F10: =IFERROR(IF($L10>0,IF(INDEX('Invullen groen'!$H:$H,$L10)=0,"",INT(INDEX('Invullen groen'!$H:$H,$L10))),""),"") | G10: =IFERROR(IF($L10>0,IF(INDEX('Invullen groen'!$I:$I,$L10)=0,"",INT(INDEX('Invullen groen'!$I:$I,$L10))),""),"") | H10: =IFERROR(IF($L10>0,IF(INDEX('Invullen groen'!$J:$J,$L10)=0,"",INT(INDEX('Invullen groen'!$J:$J,$L10))),""),"") | I10: =IFERROR(IF($L10>0,IF(INDEX('Invullen groen'!$K:$K,$L10)=0,"",INT(INDEX('Invullen groen'!$K:$K,$L10))),""),"") | J10: =IF($L10>0,IFERROR($K$1&" "&TRIM(SUBSTITUTE(SUBSTITUTE(SUBSTITUTE(SUBSTITUTE(SUBSTITUTE(SUBSTITUTE(SUBSTITUTE(SUBSTITUTE(SUBSTITUTE(SUBSTITUTE(SUBSTITUTE(SUBSTITUTE(LOWER(INDEX('Invullen groen'!$O:$O,$L10)),"2024",""),"2025",""),"2026",""),"2027",""),"2028",""),"2029",""),"taakveld ",""),"installaties","inst"),"ruwbouw","ruwb"),"afbouw","afb"),"bijstelling","bijst"),"investeringen","invest")),""),"") | L10: =IFERROR(MATCH(ROW()-4,'Invullen groen'!$P$17:$P$109,0)+16,0)
A11: =IFERROR(IF($L11>0,INDEX('Invullen groen'!$E:$E,$L11),""),"") | B11: =IFERROR(IF($L11>0,IF(INDEX('Invullen groen'!$F:$F,$L11)>0,INDEX('Invullen groen'!$F:$F,$L11),""),""),"") | C11: =IFERROR(IF($L11>0,IF(INDEX('Invullen groen'!$N:$N,$L11)>0,INDEX('Invullen groen'!$N:$N,$L11),""),""),"") | E11: =IFERROR(IF(LEN(J11)<=36,J11,IFERROR(LEFT(J11,FIND(CHAR(1),SUBSTITUTE(LEFT(J11,36)," ",CHAR(1),LEN(LEFT(J11,36))-LEN(SUBSTITUTE(LEFT(J11,36)," ",""))))-1),LEFT(J11,36))),"") | F11: =IFERROR(IF($L11>0,IF(INDEX('Invullen groen'!$H:$H,$L11)=0,"",INT(INDEX('Invullen groen'!$H:$H,$L11))),""),"") | G11: =IFERROR(IF($L11>0,IF(INDEX('Invullen groen'!$I:$I,$L11)=0,"",INT(INDEX('Invullen groen'!$I:$I,$L11))),""),"") | H11: =IFERROR(IF($L11>0,IF(INDEX('Invullen groen'!$J:$J,$L11)=0,"",INT(INDEX('Invullen groen'!$J:$J,$L11))),""),"") | I11: =IFERROR(IF($L11>0,IF(INDEX('Invullen groen'!$K:$K,$L11)=0,"",INT(INDEX('Invullen groen'!$K:$K,$L11))),""),"") | J11: =IF($L11>0,IFERROR($K$1&" "&TRIM(SUBSTITUTE(SUBSTITUTE(SUBSTITUTE(SUBSTITUTE(SUBSTITUTE(SUBSTITUTE(SUBSTITUTE(SUBSTITUTE(SUBSTITUTE(SUBSTITUTE(SUBSTITUTE(SUBSTITUTE(LOWER(INDEX('Invullen groen'!$O:$O,$L11)),"2024",""),"2025",""),"2026",""),"2027",""),"2028",""),"2029",""),"taakveld ",""),"installaties","inst"),"ruwbouw","ruwb"),"afbouw","afb"),"bijstelling","bijst"),"investeringen","invest")),""),"") | L11: =IFERROR(MATCH(ROW()-4,'Invullen groen'!$P$17:$P$109,0)+16,0)
A12: =IFERROR(IF($L12>0,INDEX('Invullen groen'!$E:$E,$L12),""),"") | B12: =IFERROR(IF($L12>0,IF(INDEX('Invullen groen'!$F:$F,$L12)>0,INDEX('Invullen groen'!$F:$F,$L12),""),""),"") | C12: =IFERROR(IF($L12>0,IF(INDEX('Invullen groen'!$N:$N,$L12)>0,INDEX('Invullen groen'!$N:$N,$L12),""),""),"") | E12: =IFERROR(IF(LEN(J12)<=36,J12,IFERROR(LEFT(J12,FIND(CHAR(1),SUBSTITUTE(LEFT(J12,36)," ",CHAR(1),LEN(LEFT(J12,36))-LEN(SUBSTITUTE(LEFT(J12,36)," ",""))))-1),LEFT(J12,36))),"") | F12: =IFERROR(IF($L12>0,IF(INDEX('Invullen groen'!$H:$H,$L12)=0,"",INT(INDEX('Invullen groen'!$H:$H,$L12))),""),"") | G12: =IFERROR(IF($L12>0,IF(INDEX('Invullen groen'!$I:$I,$L12)=0,"",INT(INDEX('Invullen groen'!$I:$I,$L12))),""),"") | H12: =IFERROR(IF($L12>0,IF(INDEX('Invullen groen'!$J:$J,$L12)=0,"",INT(INDEX('Invullen groen'!$J:$J,$L12))),""),"") | I12: =IFERROR(IF($L12>0,IF(INDEX('Invullen groen'!$K:$K,$L12)=0,"",INT(INDEX('Invullen groen'!$K:$K,$L12))),""),"") | J12: =IF($L12>0,IFERROR($K$1&" "&TRIM(SUBSTITUTE(SUBSTITUTE(SUBSTITUTE(SUBSTITUTE(SUBSTITUTE(SUBSTITUTE(SUBSTITUTE(SUBSTITUTE(SUBSTITUTE(SUBSTITUTE(SUBSTITUTE(SUBSTITUTE(LOWER(INDEX('Invullen groen'!$O:$O,$L12)),"2024",""),"2025",""),"2026",""),"2027",""),"2028",""),"2029",""),"taakveld ",""),"installaties","inst"),"ruwbouw","ruwb"),"afbouw","afb"),"bijstelling","bijst"),"investeringen","invest")),""),"") | L12: =IFERROR(MATCH(ROW()-4,'Invullen groen'!$P$17:$P$109,0)+16,0)
A13: =IFERROR(IF($L13>0,INDEX('Invullen groen'!$E:$E,$L13),""),"") | B13: =IFERROR(IF($L13>0,IF(INDEX('Invullen groen'!$F:$F,$L13)>0,INDEX('Invullen groen'!$F:$F,$L13),""),""),"") | C13: =IFERROR(IF($L13>0,IF(INDEX('Invullen groen'!$N:$N,$L13)>0,INDEX('Invullen groen'!$N:$N,$L13),""),""),"") | E13: =IFERROR(IF(LEN(J13)<=36,J13,IFERROR(LEFT(J13,FIND(CHAR(1),SUBSTITUTE(LEFT(J13,36)," ",CHAR(1),LEN(LEFT(J13,36))-LEN(SUBSTITUTE(LEFT(J13,36)," ",""))))-1),LEFT(J13,36))),"") | F13: =IFERROR(IF($L13>0,IF(INDEX('Invullen groen'!$H:$H,$L13)=0,"",INT(INDEX('Invullen groen'!$H:$H,$L13))),""),"") | G13: =IFERROR(IF($L13>0,IF(INDEX('Invullen groen'!$I:$I,$L13)=0,"",INT(INDEX('Invullen groen'!$I:$I,$L13))),""),"") | H13: =IFERROR(IF($L13>0,IF(INDEX('Invullen groen'!$J:$J,$L13)=0,"",INT(INDEX('Invullen groen'!$J:$J,$L13))),""),"") | I13: =IFERROR(IF($L13>0,IF(INDEX('Invullen groen'!$K:$K,$L13)=0,"",INT(INDEX('Invullen groen'!$K:$K,$L13))),""),"") | J13: =IF($L13>0,IFERROR($K$1&" "&TRIM(SUBSTITUTE(SUBSTITUTE(SUBSTITUTE(SUBSTITUTE(SUBSTITUTE(SUBSTITUTE(SUBSTITUTE(SUBSTITUTE(SUBSTITUTE(SUBSTITUTE(SUBSTITUTE(SUBSTITUTE(LOWER(INDEX('Invullen groen'!$O:$O,$L13)),"2024",""),"2025",""),"2026",""),"2027",""),"2028",""),"2029",""),"taakveld ",""),"installaties","inst"),"ruwbouw","ruwb"),"afbouw","afb"),"bijstelling","bijst"),"investeringen","invest")),""),"") | L13: =IFERROR(MATCH(ROW()-4,'Invullen groen'!$P$17:$P$109,0)+16,0)
A14: =IFERROR(IF($L14>0,INDEX('Invullen groen'!$E:$E,$L14),""),"") | B14: =IFERROR(IF($L14>0,IF(INDEX('Invullen groen'!$F:$F,$L14)>0,INDEX('Invullen groen'!$F:$F,$L14),""),""),"") | C14: =IFERROR(IF($L14>0,IF(INDEX('Invullen groen'!$N:$N,$L14)>0,INDEX('Invullen groen'!$N:$N,$L14),""),""),"") | E14: =IFERROR(IF(LEN(J14)<=36,J14,IFERROR(LEFT(J14,FIND(CHAR(1),SUBSTITUTE(LEFT(J14,36)," ",CHAR(1),LEN(LEFT(J14,36))-LEN(SUBSTITUTE(LEFT(J14,36)," ",""))))-1),LEFT(J14,36))),"") | F14: =IFERROR(IF($L14>0,IF(INDEX('Invullen groen'!$H:$H,$L14)=0,"",INT(INDEX('Invullen groen'!$H:$H,$L14))),""),"") | G14: =IFERROR(IF($L14>0,IF(INDEX('Invullen groen'!$I:$I,$L14)=0,"",INT(INDEX('Invullen groen'!$I:$I,$L14))),""),"") | H14: =IFERROR(IF($L14>0,IF(INDEX('Invullen groen'!$J:$J,$L14)=0,"",INT(INDEX('Invullen groen'!$J:$J,$L14))),""),"") | I14: =IFERROR(IF($L14>0,IF(INDEX('Invullen groen'!$K:$K,$L14)=0,"",INT(INDEX('Invullen groen'!$K:$K,$L14))),""),"") | J14: =IF($L14>0,IFERROR($K$1&" "&TRIM(SUBSTITUTE(SUBSTITUTE(SUBSTITUTE(SUBSTITUTE(SUBSTITUTE(SUBSTITUTE(SUBSTITUTE(SUBSTITUTE(SUBSTITUTE(SUBSTITUTE(SUBSTITUTE(SUBSTITUTE(LOWER(INDEX('Invullen groen'!$O:$O,$L14)),"2024",""),"2025",""),"2026",""),"2027",""),"2028",""),"2029",""),"taakveld ",""),"installaties","inst"),"ruwbouw","ruwb"),"afbouw","afb"),"bijstelling","bijst"),"investeringen","invest")),""),"") | L14: =IFERROR(MATCH(ROW()-4,'Invullen groen'!$P$17:$P$109,0)+16,0)
A15: =IFERROR(IF($L15>0,INDEX('Invullen groen'!$E:$E,$L15),""),"") | B15: =IFERROR(IF($L15>0,IF(INDEX('Invullen groen'!$F:$F,$L15)>0,INDEX('Invullen groen'!$F:$F,$L15),""),""),"") | C15: =IFERROR(IF($L15>0,IF(INDEX('Invullen groen'!$N:$N,$L15)>0,INDEX('Invullen groen'!$N:$N,$L15),""),""),"") | E15: =IFERROR(IF(LEN(J15)<=36,J15,IFERROR(LEFT(J15,FIND(CHAR(1),SUBSTITUTE(LEFT(J15,36)," ",CHAR(1),LEN(LEFT(J15,36))-LEN(SUBSTITUTE(LEFT(J15,36)," ",""))))-1),LEFT(J15,36))),"") | F15: =IFERROR(IF($L15>0,IF(INDEX('Invullen groen'!$H:$H,$L15)=0,"",INT(INDEX('Invullen groen'!$H:$H,$L15))),""),"") | G15: =IFERROR(IF($L15>0,IF(INDEX('Invullen groen'!$I:$I,$L15)=0,"",INT(INDEX('Invullen groen'!$I:$I,$L15))),""),"") | H15: =IFERROR(IF($L15>0,IF(INDEX('Invullen groen'!$J:$J,$L15)=0,"",INT(INDEX('Invullen groen'!$J:$J,$L15))),""),"") | I15: =IFERROR(IF($L15>0,IF(INDEX('Invullen groen'!$K:$K,$L15)=0,"",INT(INDEX('Invullen groen'!$K:$K,$L15))),""),"") | J15: =IF($L15>0,IFERROR($K$1&" "&TRIM(SUBSTITUTE(SUBSTITUTE(SUBSTITUTE(SUBSTITUTE(SUBSTITUTE(SUBSTITUTE(SUBSTITUTE(SUBSTITUTE(SUBSTITUTE(SUBSTITUTE(SUBSTITUTE(SUBSTITUTE(LOWER(INDEX('Invullen groen'!$O:$O,$L15)),"2024",""),"2025",""),"2026",""),"2027",""),"2028",""),"2029",""),"taakveld ",""),"installaties","inst"),"ruwbouw","ruwb"),"afbouw","afb"),"bijstelling","bijst"),"investeringen","invest")),""),"") | L15: =IFERROR(MATCH(ROW()-4,'Invullen groen'!$P$17:$P$109,0)+16,0)
A16: =IFERROR(IF($L16>0,INDEX('Invullen groen'!$E:$E,$L16),""),"") | B16: =IFERROR(IF($L16>0,IF(INDEX('Invullen groen'!$F:$F,$L16)>0,INDEX('Invullen groen'!$F:$F,$L16),""),""),"") | C16: =IFERROR(IF($L16>0,IF(INDEX('Invullen groen'!$N:$N,$L16)>0,INDEX('Invullen groen'!$N:$N,$L16),""),""),"") | E16: =IFERROR(IF(LEN(J16)<=36,J16,IFERROR(LEFT(J16,FIND(CHAR(1),SUBSTITUTE(LEFT(J16,36)," ",CHAR(1),LEN(LEFT(J16,36))-LEN(SUBSTITUTE(LEFT(J16,36)," ",""))))-1),LEFT(J16,36))),"") | F16: =IFERROR(IF($L16>0,IF(INDEX('Invullen groen'!$H:$H,$L16)=0,"",INT(INDEX('Invullen groen'!$H:$H,$L16))),""),"") | G16: =IFERROR(IF($L16>0,IF(INDEX('Invullen groen'!$I:$I,$L16)=0,"",INT(INDEX('Invullen groen'!$I:$I,$L16))),""),"") | H16: =IFERROR(IF($L16>0,IF(INDEX('Invullen groen'!$J:$J,$L16)=0,"",INT(INDEX('Invullen groen'!$J:$J,$L16))),""),"") | I16: =IFERROR(IF($L16>0,IF(INDEX('Invullen groen'!$K:$K,$L16)=0,"",INT(INDEX('Invullen groen'!$K:$K,$L16))),""),"") | J16: =IF($L16>0,IFERROR($K$1&" "&TRIM(SUBSTITUTE(SUBSTITUTE(SUBSTITUTE(SUBSTITUTE(SUBSTITUTE(SUBSTITUTE(SUBSTITUTE(SUBSTITUTE(SUBSTITUTE(SUBSTITUTE(SUBSTITUTE(SUBSTITUTE(LOWER(INDEX('Invullen groen'!$O:$O,$L16)),"2024",""),"2025",""),"2026",""),"2027",""),"2028",""),"2029",""),"taakveld ",""),"installaties","inst"),"ruwbouw","ruwb"),"afbouw","afb"),"bijstelling","bijst"),"investeringen","invest")),""),"") | L16: =IFERROR(MATCH(ROW()-4,'Invullen groen'!$P$17:$P$109,0)+16,0)
A17: =IFERROR(IF($L17>0,INDEX('Invullen groen'!$E:$E,$L17),""),"") | B17: =IFERROR(IF($L17>0,IF(INDEX('Invullen groen'!$F:$F,$L17)>0,INDEX('Invullen groen'!$F:$F,$L17),""),""),"") | C17: =IFERROR(IF($L17>0,IF(INDEX('Invullen groen'!$N:$N,$L17)>0,INDEX('Invullen groen'!$N:$N,$L17),""),""),"") | E17: =IFERROR(IF(LEN(J17)<=36,J17,IFERROR(LEFT(J17,FIND(CHAR(1),SUBSTITUTE(LEFT(J17,36)," ",CHAR(1),LEN(LEFT(J17,36))-LEN(SUBSTITUTE(LEFT(J17,36)," ",""))))-1),LEFT(J17,36))),"") | F17: =IFERROR(IF($L17>0,IF(INDEX('Invullen groen'!$H:$H,$L17)=0,"",INT(INDEX('Invullen groen'!$H:$H,$L17))),""),"") | G17: =IFERROR(IF($L17>0,IF(INDEX('Invullen groen'!$I:$I,$L17)=0,"",INT(INDEX('Invullen groen'!$I:$I,$L17))),""),"") | H17: =IFERROR(IF($L17>0,IF(INDEX('Invullen groen'!$J:$J,$L17)=0,"",INT(INDEX('Invullen groen'!$J:$J,$L17))),""),"") | I17: =IFERROR(IF($L17>0,IF(INDEX('Invullen groen'!$K:$K,$L17)=0,"",INT(INDEX('Invullen groen'!$K:$K,$L17))),""),"") | J17: =IF($L17>0,IFERROR($K$1&" "&TRIM(SUBSTITUTE(SUBSTITUTE(SUBSTITUTE(SUBSTITUTE(SUBSTITUTE(SUBSTITUTE(SUBSTITUTE(SUBSTITUTE(SUBSTITUTE(SUBSTITUTE(SUBSTITUTE(SUBSTITUTE(LOWER(INDEX('Invullen groen'!$O:$O,$L17)),"2024",""),"2025",""),"2026",""),"2027",""),"2028",""),"2029",""),"taakveld ",""),"installaties","inst"),"ruwbouw","ruwb"),"afbouw","afb"),"bijstelling","bijst"),"investeringen","invest")),""),"") | L17: =IFERROR(MATCH(ROW()-4,'Invullen groen'!$P$17:$P$109,0)+16,0)
... A104: =IFERROR(IF($L104>0,INDEX('Invullen groen'!$E:$E,$L104),""),"") | B104: =IFERROR(IF($L104>0,IF(INDEX('Invullen groen'!$F:$F,$L104)>0,INDEX('Invullen groen'!$F:$F,$L104),""),""),"") | C104: =IFERROR(IF($L104>0,IF(INDEX('Invullen groen'!$N:$N,$L104)>0,INDEX('Invullen groen'!$N:$N,$L104),""),""),"") | E104: =IFERROR(IF(LEN(J104)<=36,J104,IFERROR(LEFT(J104,FIND(CHAR(1),SUBSTITUTE(LEFT(J104,36)," ",CHAR(1),LEN(LEFT(J104,36))-LEN(SUBSTITUTE(LEFT(J104,36)," ",""))))-1),LEFT(J104,36))),"") | F104: =IFERROR(IF($L104>0,IF(INDEX('Invullen groen'!$H:$H,$L104)=0,"",INT(INDEX('Invullen groen'!$H:$H,$L104))),""),"") | G104: =IFERROR(IF($L104>0,IF(INDEX('Invullen groen'!$I:$I,$L104)=0,"",INT(INDEX('Invullen groen'!$I:$I,$L104))),""),"") | H104: =IFERROR(IF($L104>0,IF(INDEX('Invullen groen'!$J:$J,$L104)=0,"",INT(INDEX('Invullen groen'!$J:$J,$L104))),""),"") | I104: =IFERROR(IF($L104>0,IF(INDEX('Invullen groen'!$K:$K,$L104)=0,"",INT(INDEX('Invullen groen'!$K:$K,$L104))),""),"") | J104: =IF($L104>0,IFERROR($K$1&" "&TRIM(SUBSTITUTE(SUBSTITUTE(SUBSTITUTE(SUBSTITUTE(SUBSTITUTE(SUBSTITUTE(SUBSTITUTE(SUBSTITUTE(SUBSTITUTE(SUBSTITUTE(SUBSTITUTE(SUBSTITUTE(LOWER(INDEX('Invullen groen'!$O:$O,$L104)),"2024",""),"2025",""),"2026",""),"2027",""),"2028",""),"2029",""),"taakveld ",""),"installaties","inst"),"ruwbouw","ruwb"),"afbouw","afb"),"bijstelling","bijst"),"investeringen","invest")),""),"") | L104: =IFERROR(MATCH(ROW()-4,'Invullen groen'!$P$17:$P$109,0)+16,0)
A105: =IF($L105>0,"+","") | B105: =IFERROR(IF($L105>0,IF(INDEX('Invullen groen'!$F:$F,$L105)>0,INDEX('Invullen groen'!$F:$F,$L105),""),""),"") | C105: =IFERROR(IF($L105>0,IF(INDEX('Invullen groen'!$N:$N,$L105)>0,INDEX('Invullen groen'!$N:$N,$L105),""),""),"") | E105: =IFERROR(IF(LEN(J105)<=36,J105,IFERROR(LEFT(J105,FIND(CHAR(1),SUBSTITUTE(LEFT(J105,36)," ",CHAR(1),LEN(LEFT(J105,36))-LEN(SUBSTITUTE(LEFT(J105,36)," ",""))))-1),LEFT(J105,36))),"") | F105: =IFERROR(IF($L105>0,IF(INDEX('Invullen groen'!$H:$H,$L105)=0,"",INT(INDEX('Invullen groen'!$H:$H,$L105))),""),"") | G105: =IFERROR(IF($L105>0,IF(INDEX('Invullen groen'!$I:$I,$L105)=0,"",INT(INDEX('Invullen groen'!$I:$I,$L105))),""),"") | H105: =IFERROR(IF($L105>0,IF(INDEX('Invullen groen'!$J:$J,$L105)=0,"",INT(INDEX('Invullen groen'!$J:$J,$L105))),""),"") | I105: =IFERROR(IF($L105>0,IF(INDEX('Invullen groen'!$K:$K,$L105)=0,"",INT(INDEX('Invullen groen'!$K:$K,$L105))),""),"") | J105: =IF($L105>0,IFERROR($K$1&" "&TRIM(SUBSTITUTE(SUBSTITUTE(SUBSTITUTE(SUBSTITUTE(SUBSTITUTE(SUBSTITUTE(SUBSTITUTE(SUBSTITUTE(SUBSTITUTE(SUBSTITUTE(SUBSTITUTE(SUBSTITUTE(LOWER(INDEX('Invullen groen'!$O:$O,$L105)),"2024",""),"2025",""),"2026",""),"2027",""),"2028",""),"2029",""),"taakveld ",""),"installaties","inst"),"ruwbouw","ruwb"),"afbouw","afb"),"bijstelling","bijst"),"investeringen","invest")),""),"") | L105: =IFERROR(MATCH(ROW()-104,'Invullen groen'!$S$121:$S$272,0)+120,0)
A106: =IF($L106>0,"+","") | B106: =IFERROR(IF($L106>0,IF(INDEX('Invullen groen'!$F:$F,$L106)>0,INDEX('Invullen groen'!$F:$F,$L106),""),""),"") | C106: =IFERROR(IF($L106>0,IF(INDEX('Invullen groen'!$N:$N,$L106)>0,INDEX('Invullen groen'!$N:$N,$L106),""),""),"") | E106: =IFERROR(IF(LEN(J106)<=36,J106,IFERROR(LEFT(J106,FIND(CHAR(1),SUBSTITUTE(LEFT(J106,36)," ",CHAR(1),LEN(LEFT(J106,36))-LEN(SUBSTITUTE(LEFT(J106,36)," ",""))))-1),LEFT(J106,36))),"") | F106: =IFERROR(IF($L106>0,IF(INDEX('Invullen groen'!$H:$H,$L106)=0,"",INT(INDEX('Invullen groen'!$H:$H,$L106))),""),"") | G106: =IFERROR(IF($L106>0,IF(INDEX('Invullen groen'!$I:$I,$L106)=0,"",INT(INDEX('Invullen groen'!$I:$I,$L106))),""),"") | H106: =IFERROR(IF($L106>0,IF(INDEX('Invullen groen'!$J:$J,$L106)=0,"",INT(INDEX('Invullen groen'!$J:$J,$L106))),""),"") | I106: =IFERROR(IF($L106>0,IF(INDEX('Invullen groen'!$K:$K,$L106)=0,"",INT(INDEX('Invullen groen'!$K:$K,$L106))),""),"") | J106: =IF($L106>0,IFERROR($K$1&" "&TRIM(SUBSTITUTE(SUBSTITUTE(SUBSTITUTE(SUBSTITUTE(SUBSTITUTE(SUBSTITUTE(SUBSTITUTE(SUBSTITUTE(SUBSTITUTE(SUBSTITUTE(SUBSTITUTE(SUBSTITUTE(LOWER(INDEX('Invullen groen'!$O:$O,$L106)),"2024",""),"2025",""),"2026",""),"2027",""),"2028",""),"2029",""),"taakveld ",""),"installaties","inst"),"ruwbouw","ruwb"),"afbouw","afb"),"bijstelling","bijst"),"investeringen","invest")),""),"") | L106: =IFERROR(MATCH(ROW()-104,'Invullen groen'!$S$121:$S$272,0)+120,0)
A107: =IF($L107>0,"+","") | B107: =IFERROR(IF($L107>0,IF(INDEX('Invullen groen'!$F:$F,$L107)>0,INDEX('Invullen groen'!$F:$F,$L107),""),""),"") | C107: =IFERROR(IF($L107>0,IF(INDEX('Invullen groen'!$N:$N,$L107)>0,INDEX('Invullen groen'!$N:$N,$L107),""),""),"") | E107: =IFERROR(IF(LEN(J107)<=36,J107,IFERROR(LEFT(J107,FIND(CHAR(1),SUBSTITUTE(LEFT(J107,36)," ",CHAR(1),LEN(LEFT(J107,36))-LEN(SUBSTITUTE(LEFT(J107,36)," ",""))))-1),LEFT(J107,36))),"") | F107: =IFERROR(IF($L107>0,IF(INDEX('Invullen groen'!$H:$H,$L107)=0,"",INT(INDEX('Invullen groen'!$H:$H,$L107))),""),"") | G107: =IFERROR(IF($L107>0,IF(INDEX('Invullen groen'!$I:$I,$L107)=0,"",INT(INDEX('Invullen groen'!$I:$I,$L107))),""),"") | H107: =IFERROR(IF($L107>0,IF(INDEX('Invullen groen'!$J:$J,$L107)=0,"",INT(INDEX('Invullen groen'!$J:$J,$L107))),""),"") | I107: =IFERROR(IF($L107>0,IF(INDEX('Invullen groen'!$K:$K,$L107)=0,"",INT(INDEX('Invullen groen'!$K:$K,$L107))),""),"") | J107: =IF($L107>0,IFERROR($K$1&" "&TRIM(SUBSTITUTE(SUBSTITUTE(SUBSTITUTE(SUBSTITUTE(SUBSTITUTE(SUBSTITUTE(SUBSTITUTE(SUBSTITUTE(SUBSTITUTE(SUBSTITUTE(SUBSTITUTE(SUBSTITUTE(LOWER(INDEX('Invullen groen'!$O:$O,$L107)),"2024",""),"2025",""),"2026",""),"2027",""),"2028",""),"2029",""),"taakveld ",""),"installaties","inst"),"ruwbouw","ruwb"),"afbouw","afb"),"bijstelling","bijst"),"investeringen","invest")),""),"") | L107: =IFERROR(MATCH(ROW()-104,'Invullen groen'!$S$121:$S$272,0)+120,0)
A108: =IF($L108>0,"+","") | B108: =IFERROR(IF($L108>0,IF(INDEX('Invullen groen'!$F:$F,$L108)>0,INDEX('Invullen groen'!$F:$F,$L108),""),""),"") | C108: =IFERROR(IF($L108>0,IF(INDEX('Invullen groen'!$N:$N,$L108)>0,INDEX('Invullen groen'!$N:$N,$L108),""),""),"") | E108: =IFERROR(IF(LEN(J108)<=36,J108,IFERROR(LEFT(J108,FIND(CHAR(1),SUBSTITUTE(LEFT(J108,36)," ",CHAR(1),LEN(LEFT(J108,36))-LEN(SUBSTITUTE(LEFT(J108,36)," ",""))))-1),LEFT(J108,36))),"") | F108: =IFERROR(IF($L108>0,IF(INDEX('Invullen groen'!$H:$H,$L108)=0,"",INT(INDEX('Invullen groen'!$H:$H,$L108))),""),"") | G108: =IFERROR(IF($L108>0,IF(INDEX('Invullen groen'!$I:$I,$L108)=0,"",INT(INDEX('Invullen groen'!$I:$I,$L108))),""),"") | H108: =IFERROR(IF($L108>0,IF(INDEX('Invullen groen'!$J:$J,$L108)=0,"",INT(INDEX('Invullen groen'!$J:$J,$L108))),""),"") | I108: =IFERROR(IF($L108>0,IF(INDEX('Invullen groen'!$K:$K,$L108)=0,"",INT(INDEX('Invullen groen'!$K:$K,$L108))),""),"") | J108: =IF($L108>0,IFERROR($K$1&" "&TRIM(SUBSTITUTE(SUBSTITUTE(SUBSTITUTE(SUBSTITUTE(SUBSTITUTE(SUBSTITUTE(SUBSTITUTE(SUBSTITUTE(SUBSTITUTE(SUBSTITUTE(SUBSTITUTE(SUBSTITUTE(LOWER(INDEX('Invullen groen'!$O:$O,$L108)),"2024",""),"2025",""),"2026",""),"2027",""),"2028",""),"2029",""),"taakveld ",""),"installaties","inst"),"ruwbouw","ruwb"),"afbouw","afb"),"bijstelling","bijst"),"investeringen","invest")),""),"") | L108: =IFERROR(MATCH(ROW()-104,'Invullen groen'!$S$121:$S$272,0)+120,0)
A109: =IF($L109>0,"+","") | B109: =IFERROR(IF($L109>0,IF(INDEX('Invullen groen'!$F:$F,$L109)>0,INDEX('Invullen groen'!$F:$F,$L109),""),""),"") | C109: =IFERROR(IF($L109>0,IF(INDEX('Invullen groen'!$N:$N,$L109)>0,INDEX('Invullen groen'!$N:$N,$L109),""),""),"") | E109: =IFERROR(IF(LEN(J109)<=36,J109,IFERROR(LEFT(J109,FIND(CHAR(1),SUBSTITUTE(LEFT(J109,36)," ",CHAR(1),LEN(LEFT(J109,36))-LEN(SUBSTITUTE(LEFT(J109,36)," ",""))))-1),LEFT(J109,36))),"") | F109: =IFERROR(IF($L109>0,IF(INDEX('Invullen groen'!$H:$H,$L109)=0,"",INT(INDEX('Invullen groen'!$H:$H,$L109))),""),"") | G109: =IFERROR(IF($L109>0,IF(INDEX('Invullen groen'!$I:$I,$L109)=0,"",INT(INDEX('Invullen groen'!$I:$I,$L109))),""),"") | H109: =IFERROR(IF($L109>0,IF(INDEX('Invullen groen'!$J:$J,$L109)=0,"",INT(INDEX('Invullen groen'!$J:$J,$L109))),""),"") | I109: =IFERROR(IF($L109>0,IF(INDEX('Invullen groen'!$K:$K,$L109)=0,"",INT(INDEX('Invullen groen'!$K:$K,$L109))),""),"") | J109: =IF($L109>0,IFERROR($K$1&" "&TRIM(SUBSTITUTE(SUBSTITUTE(SUBSTITUTE(SUBSTITUTE(SUBSTITUTE(SUBSTITUTE(SUBSTITUTE(SUBSTITUTE(SUBSTITUTE(SUBSTITUTE(SUBSTITUTE(SUBSTITUTE(LOWER(INDEX('Invullen groen'!$O:$O,$L109)),"2024",""),"2025",""),"2026",""),"2027",""),"2028",""),"2029",""),"taakveld ",""),"installaties","inst"),"ruwbouw","ruwb"),"afbouw","afb"),"bijstelling","bijst"),"investeringen","invest")),""),"") | L109: =IFERROR(MATCH(ROW()-104,'Invullen groen'!$S$121:$S$272,0)+120,0)
A110: =IF($L110>0,"+","") | B110: =IFERROR(IF($L110>0,IF(INDEX('Invullen groen'!$F:$F,$L110)>0,INDEX('Invullen groen'!$F:$F,$L110),""),""),"") | C110: =IFERROR(IF($L110>0,IF(INDEX('Invullen groen'!$N:$N,$L110)>0,INDEX('Invullen groen'!$N:$N,$L110),""),""),"") | E110: =IFERROR(IF(LEN(J110)<=36,J110,IFERROR(LEFT(J110,FIND(CHAR(1),SUBSTITUTE(LEFT(J110,36)," ",CHAR(1),LEN(LEFT(J110,36))-LEN(SUBSTITUTE(LEFT(J110,36)," ",""))))-1),LEFT(J110,36))),"") | F110: =IFERROR(IF($L110>0,IF(INDEX('Invullen groen'!$H:$H,$L110)=0,"",INT(INDEX('Invullen groen'!$H:$H,$L110))),""),"") | G110: =IFERROR(IF($L110>0,IF(INDEX('Invullen groen'!$I:$I,$L110)=0,"",INT(INDEX('Invullen groen'!$I:$I,$L110))),""),"") | H110: =IFERROR(IF($L110>0,IF(INDEX('Invullen groen'!$J:$J,$L110)=0,"",INT(INDEX('Invullen groen'!$J:$J,$L110))),""),"") | I110: =IFERROR(IF($L110>0,IF(INDEX('Invullen groen'!$K:$K,$L110)=0,"",INT(INDEX('Invullen groen'!$K:$K,$L110))),""),"") | J110: =IF($L110>0,IFERROR($K$1&" "&TRIM(SUBSTITUTE(SUBSTITUTE(SUBSTITUTE(SUBSTITUTE(SUBSTITUTE(SUBSTITUTE(SUBSTITUTE(SUBSTITUTE(SUBSTITUTE(SUBSTITUTE(SUBSTITUTE(SUBSTITUTE(LOWER(INDEX('Invullen groen'!$O:$O,$L110)),"2024",""),"2025",""),"2026",""),"2027",""),"2028",""),"2029",""),"taakveld ",""),"installaties","inst"),"ruwbouw","ruwb"),"afbouw","afb"),"bijstelling","bijst"),"investeringen","invest")),""),"") | L110: =IFERROR(MATCH(ROW()-104,'Invullen groen'!$S$121:$S$272,0)+120,0)
A111: =IF($L111>0,"+","") | B111: =IFERROR(IF($L111>0,IF(INDEX('Invullen groen'!$F:$F,$L111)>0,INDEX('Invullen groen'!$F:$F,$L111),""),""),"") | C111: =IFERROR(IF($L111>0,IF(INDEX('Invullen groen'!$N:$N,$L111)>0,INDEX('Invullen groen'!$N:$N,$L111),""),""),"") | E111: =IFERROR(IF(LEN(J111)<=36,J111,IFERROR(LEFT(J111,FIND(CHAR(1),SUBSTITUTE(LEFT(J111,36)," ",CHAR(1),LEN(LEFT(J111,36))-LEN(SUBSTITUTE(LEFT(J111,36)," ",""))))-1),LEFT(J111,36))),"") | F111: =IFERROR(IF($L111>0,IF(INDEX('Invullen groen'!$H:$H,$L111)=0,"",INT(INDEX('Invullen groen'!$H:$H,$L111))),""),"") | G111: =IFERROR(IF($L111>0,IF(INDEX('Invullen groen'!$I:$I,$L111)=0,"",INT(INDEX('Invullen groen'!$I:$I,$L111))),""),"") | H111: =IFERROR(IF($L111>0,IF(INDEX('Invullen groen'!$J:$J,$L111)=0,"",INT(INDEX('Invullen groen'!$J:$J,$L111))),""),"") | I111: =IFERROR(IF($L111>0,IF(INDEX('Invullen groen'!$K:$K,$L111)=0,"",INT(INDEX('Invullen groen'!$K:$K,$L111))),""),"") | J111: =IF($L111>0,IFERROR($K$1&" "&TRIM(SUBSTITUTE(SUBSTITUTE(SUBSTITUTE(SUBSTITUTE(SUBSTITUTE(SUBSTITUTE(SUBSTITUTE(SUBSTITUTE(SUBSTITUTE(SUBSTITUTE(SUBSTITUTE(SUBSTITUTE(LOWER(INDEX('Invullen groen'!$O:$O,$L111)),"2024",""),"2025",""),"2026",""),"2027",""),"2028",""),"2029",""),"taakveld ",""),"installaties","inst"),"ruwbouw","ruwb"),"afbouw","afb"),"bijstelling","bijst"),"investeringen","invest")),""),"") | L111: =IFERROR(MATCH(ROW()-104,'Invullen groen'!$S$121:$S$272,0)+120,0)
A112: =IF($L112>0,"+","") | B112: =IFERROR(IF($L112>0,IF(INDEX('Invullen groen'!$F:$F,$L112)>0,INDEX('Invullen groen'!$F:$F,$L112),""),""),"") | C112: =IFERROR(IF($L112>0,IF(INDEX('Invullen groen'!$N:$N,$L112)>0,INDEX('Invullen groen'!$N:$N,$L112),""),""),"") | E112: =IFERROR(IF(LEN(J112)<=36,J112,IFERROR(LEFT(J112,FIND(CHAR(1),SUBSTITUTE(LEFT(J112,36)," ",CHAR(1),LEN(LEFT(J112,36))-LEN(SUBSTITUTE(LEFT(J112,36)," ",""))))-1),LEFT(J112,36))),"") | F112: =IFERROR(IF($L112>0,IF(INDEX('Invullen groen'!$H:$H,$L112)=0,"",INT(INDEX('Invullen groen'!$H:$H,$L112))),""),"") | G112: =IFERROR(IF($L112>0,IF(INDEX('Invullen groen'!$I:$I,$L112)=0,"",INT(INDEX('Invullen groen'!$I:$I,$L112))),""),"") | H112: =IFERROR(IF($L112>0,IF(INDEX('Invullen groen'!$J:$J,$L112)=0,"",INT(INDEX('Invullen groen'!$J:$J,$L112))),""),"") | I112: =IFERROR(IF($L112>0,IF(INDEX('Invullen groen'!$K:$K,$L112)=0,"",INT(INDEX('Invullen groen'!$K:$K,$L112))),""),"") | J112: =IF($L112>0,IFERROR($K$1&" "&TRIM(SUBSTITUTE(SUBSTITUTE(SUBSTITUTE(SUBSTITUTE(SUBSTITUTE(SUBSTITUTE(SUBSTITUTE(SUBSTITUTE(SUBSTITUTE(SUBSTITUTE(SUBSTITUTE(SUBSTITUTE(LOWER(INDEX('Invullen groen'!$O:$O,$L112)),"2024",""),"2025",""),"2026",""),"2027",""),"2028",""),"2029",""),"taakveld ",""),"installaties","inst"),"ruwbouw","ruwb"),"afbouw","afb"),"bijstelling","bijst"),"investeringen","invest")),""),"") | L112: =IFERROR(MATCH(ROW()-104,'Invullen groen'!$S$121:$S$272,0)+120,0)
A113: =IF($L113>0,"+","") | B113: =IFERROR(IF($L113>0,IF(INDEX('Invullen groen'!$F:$F,$L113)>0,INDEX('Invullen groen'!$F:$F,$L113),""),""),"") | C113: =IFERROR(IF($L113>0,IF(INDEX('Invullen groen'!$N:$N,$L113)>0,INDEX('Invullen groen'!$N:$N,$L113),""),""),"") | E113: =IFERROR(IF(LEN(J113)<=36,J113,IFERROR(LEFT(J113,FIND(CHAR(1),SUBSTITUTE(LEFT(J113,36)," ",CHAR(1),LEN(LEFT(J113,36))-LEN(SUBSTITUTE(LEFT(J113,36)," ",""))))-1),LEFT(J113,36))),"") | F113: =IFERROR(IF($L113>0,IF(INDEX('Invullen groen'!$H:$H,$L113)=0,"",INT(INDEX('Invullen groen'!$H:$H,$L113))),""),"") | G113: =IFERROR(IF($L113>0,IF(INDEX('Invullen groen'!$I:$I,$L113)=0,"",INT(INDEX('Invullen groen'!$I:$I,$L113))),""),"") | H113: =IFERROR(IF($L113>0,IF(INDEX('Invullen groen'!$J:$J,$L113)=0,"",INT(INDEX('Invullen groen'!$J:$J,$L113))),""),"") | I113: =IFERROR(IF($L113>0,IF(INDEX('Invullen groen'!$K:$K,$L113)=0,"",INT(INDEX('Invullen groen'!$K:$K,$L113))),""),"") | J113: =IF($L113>0,IFERROR($K$1&" "&TRIM(SUBSTITUTE(SUBSTITUTE(SUBSTITUTE(SUBSTITUTE(SUBSTITUTE(SUBSTITUTE(SUBSTITUTE(SUBSTITUTE(SUBSTITUTE(SUBSTITUTE(SUBSTITUTE(SUBSTITUTE(LOWER(INDEX('Invullen groen'!$O:$O,$L113)),"2024",""),"2025",""),"2026",""),"2027",""),"2028",""),"2029",""),"taakveld ",""),"installaties","inst"),"ruwbouw","ruwb"),"afbouw","afb"),"bijstelling","bijst"),"investeringen","invest")),""),"") | L113: =IFERROR(MATCH(ROW()-104,'Invullen groen'!$S$121:$S$272,0)+120,0)
A114: =IF($L114>0,"+","") | B114: =IFERROR(IF($L114>0,IF(INDEX('Invullen groen'!$F:$F,$L114)>0,INDEX('Invullen groen'!$F:$F,$L114),""),""),"") | C114: =IFERROR(IF($L114>0,IF(INDEX('Invullen groen'!$N:$N,$L114)>0,INDEX('Invullen groen'!$N:$N,$L114),""),""),"") | E114: =IFERROR(IF(LEN(J114)<=36,J114,IFERROR(LEFT(J114,FIND(CHAR(1),SUBSTITUTE(LEFT(J114,36)," ",CHAR(1),LEN(LEFT(J114,36))-LEN(SUBSTITUTE(LEFT(J114,36)," ",""))))-1),LEFT(J114,36))),"") | F114: =IFERROR(IF($L114>0,IF(INDEX('Invullen groen'!$H:$H,$L114)=0,"",INT(INDEX('Invullen groen'!$H:$H,$L114))),""),"") | G114: =IFERROR(IF($L114>0,IF(INDEX('Invullen groen'!$I:$I,$L114)=0,"",INT(INDEX('Invullen groen'!$I:$I,$L114))),""),"") | H114: =IFERROR(IF($L114>0,IF(INDEX('Invullen groen'!$J:$J,$L114)=0,"",INT(INDEX('Invullen groen'!$J:$J,$L114))),""),"") | I114: =IFERROR(IF($L114>0,IF(INDEX('Invullen groen'!$K:$K,$L114)=0,"",INT(INDEX('Invullen groen'!$K:$K,$L114))),""),"") | J114: =IF($L114>0,IFERROR($K$1&" "&TRIM(SUBSTITUTE(SUBSTITUTE(SUBSTITUTE(SUBSTITUTE(SUBSTITUTE(SUBSTITUTE(SUBSTITUTE(SUBSTITUTE(SUBSTITUTE(SUBSTITUTE(SUBSTITUTE(SUBSTITUTE(LOWER(INDEX('Invullen groen'!$O:$O,$L114)),"2024",""),"2025",""),"2026",""),"2027",""),"2028",""),"2029",""),"taakveld ",""),"installaties","inst"),"ruwbouw","ruwb"),"afbouw","afb"),"bijstelling","bijst"),"investeringen","invest")),""),"") | L114: =IFERROR(MATCH(ROW()-104,'Invullen groen'!$S$121:$S$272,0)+120,0)
A115: =IF($L115>0,"+","") | B115: =IFERROR(IF($L115>0,IF(INDEX('Invullen groen'!$F:$F,$L115)>0,INDEX('Invullen groen'!$F:$F,$L115),""),""),"") | C115: =IFERROR(IF($L115>0,IF(INDEX('Invullen groen'!$N:$N,$L115)>0,INDEX('Invullen groen'!$N:$N,$L115),""),""),"") | E115: =IFERROR(IF(LEN(J115)<=36,J115,IFERROR(LEFT(J115,FIND(CHAR(1),SUBSTITUTE(LEFT(J115,36)," ",CHAR(1),LEN(LEFT(J115,36))-LEN(SUBSTITUTE(LEFT(J115,36)," ",""))))-1),LEFT(J115,36))),"") | F115: =IFERROR(IF($L115>0,IF(INDEX('Invullen groen'!$H:$H,$L115)=0,"",INT(INDEX('Invullen groen'!$H:$H,$L115))),""),"") | G115: =IFERROR(IF($L115>0,IF(INDEX('Invullen groen'!$I:$I,$L115)=0,"",INT(INDEX('Invullen groen'!$I:$I,$L115))),""),"") | H115: =IFERROR(IF($L115>0,IF(INDEX('Invullen groen'!$J:$J,$L115)=0,"",INT(INDEX('Invullen groen'!$J:$J,$L115))),""),"") | I115: =IFERROR(IF($L115>0,IF(INDEX('Invullen groen'!$K:$K,$L115)=0,"",INT(INDEX('Invullen groen'!$K:$K,$L115))),""),"") | J115: =IF($L115>0,IFERROR($K$1&" "&TRIM(SUBSTITUTE(SUBSTITUTE(SUBSTITUTE(SUBSTITUTE(SUBSTITUTE(SUBSTITUTE(SUBSTITUTE(SUBSTITUTE(SUBSTITUTE(SUBSTITUTE(SUBSTITUTE(SUBSTITUTE(LOWER(INDEX('Invullen groen'!$O:$O,$L115)),"2024",""),"2025",""),"2026",""),"2027",""),"2028",""),"2029",""),"taakveld ",""),"installaties","inst"),"ruwbouw","ruwb"),"afbouw","afb"),"bijstelling","bijst"),"investeringen","invest")),""),"") | L115: =IFERROR(MATCH(ROW()-104,'Invullen groen'!$S$121:$S$272,0)+120,0)
A116: =IF($L116>0,"+","") | B116: =IFERROR(IF($L116>0,IF(INDEX('Invullen groen'!$F:$F,$L116)>0,INDEX('Invullen groen'!$F:$F,$L116),""),""),"") | C116: =IFERROR(IF($L116>0,IF(INDEX('Invullen groen'!$N:$N,$L116)>0,INDEX('Invullen groen'!$N:$N,$L116),""),""),"") | E116: =IFERROR(IF(LEN(J116)<=36,J116,IFERROR(LEFT(J116,FIND(CHAR(1),SUBSTITUTE(LEFT(J116,36)," ",CHAR(1),LEN(LEFT(J116,36))-LEN(SUBSTITUTE(LEFT(J116,36)," ",""))))-1),LEFT(J116,36))),"") | F116: =IFERROR(IF($L116>0,IF(INDEX('Invullen groen'!$H:$H,$L116)=0,"",INT(INDEX('Invullen groen'!$H:$H,$L116))),""),"") | G116: =IFERROR(IF($L116>0,IF(INDEX('Invullen groen'!$I:$I,$L116)=0,"",INT(INDEX('Invullen groen'!$I:$I,$L116))),""),"") | H116: =IFERROR(IF($L116>0,IF(INDEX('Invullen groen'!$J:$J,$L116)=0,"",INT(INDEX('Invullen groen'!$J:$J,$L116))),""),"") | I116: =IFERROR(IF($L116>0,IF(INDEX('Invullen groen'!$K:$K,$L116)=0,"",INT(INDEX('Invullen groen'!$K:$K,$L116))),""),"") | J116: =IF($L116>0,IFERROR($K$1&" "&TRIM(SUBSTITUTE(SUBSTITUTE(SUBSTITUTE(SUBSTITUTE(SUBSTITUTE(SUBSTITUTE(SUBSTITUTE(SUBSTITUTE(SUBSTITUTE(SUBSTITUTE(SUBSTITUTE(SUBSTITUTE(LOWER(INDEX('Invullen groen'!$O:$O,$L116)),"2024",""),"2025",""),"2026",""),"2027",""),"2028",""),"2029",""),"taakveld ",""),"installaties","inst"),"ruwbouw","ruwb"),"afbouw","afb"),"bijstelling","bijst"),"investeringen","invest")),""),"") | L116: =IFERROR(MATCH(ROW()-104,'Invullen groen'!$S$121:$S$272,0)+120,0)
... A250: =IF($L250>0,"+","") | B250: =IFERROR(IF($L250>0,IF(INDEX('Invullen groen'!$F:$F,$L250)>0,INDEX('Invullen groen'!$F:$F,$L250),""),""),"") | C250: =IFERROR(IF($L250>0,IF(INDEX('Invullen groen'!$N:$N,$L250)>0,INDEX('Invullen groen'!$N:$N,$L250),""),""),"") | E250: =IFERROR(IF(LEN(J250)<=36,J250,IFERROR(LEFT(J250,FIND(CHAR(1),SUBSTITUTE(LEFT(J250,36)," ",CHAR(1),LEN(LEFT(J250,36))-LEN(SUBSTITUTE(LEFT(J250,36)," ",""))))-1),LEFT(J250,36))),"") | F250: =IFERROR(IF($L250>0,IF(INDEX('Invullen groen'!$H:$H,$L250)=0,"",INT(INDEX('Invullen groen'!$H:$H,$L250))),""),"") | G250: =IFERROR(IF($L250>0,IF(INDEX('Invullen groen'!$I:$I,$L250)=0,"",INT(INDEX('Invullen groen'!$I:$I,$L250))),""),"") | H250: =IFERROR(IF($L250>0,IF(INDEX('Invullen groen'!$J:$J,$L250)=0,"",INT(INDEX('Invullen groen'!$J:$J,$L250))),""),"") | I250: =IFERROR(IF($L250>0,IF(INDEX('Invullen groen'!$K:$K,$L250)=0,"",INT(INDEX('Invullen groen'!$K:$K,$L250))),""),"") | J250: =IF($L250>0,IFERROR($K$1&" "&TRIM(SUBSTITUTE(SUBSTITUTE(SUBSTITUTE(SUBSTITUTE(SUBSTITUTE(SUBSTITUTE(SUBSTITUTE(SUBSTITUTE(SUBSTITUTE(SUBSTITUTE(SUBSTITUTE(SUBSTITUTE(LOWER(INDEX('Invullen groen'!$O:$O,$L250)),"2024",""),"2025",""),"2026",""),"2027",""),"2028",""),"2029",""),"taakveld ",""),"installaties","inst"),"ruwbouw","ruwb"),"afbouw","afb"),"bijstelling","bijst"),"investeringen","invest")),""),"") | L250: =IFERROR(MATCH(ROW()-104,'Invullen groen'!$S$121:$S$272,0)+120,0)
A251: =IF(SUM(F105:I250)=0,"",2999999) | B251: =IF(SUM(F105:I250)=0,"",86100) | E251: =IF(SUM(F105:I250)=0,"",$K$1&" sluitrekening balans") | F251: =IFERROR(IF(SUM(F105:F250)=0,"",-SUM(F105:F250)),"") | G251: =IFERROR(IF(SUM(G105:G250)=0,"",-SUM(G105:G250)),"") | H251: =IFERROR(IF(SUM(H105:H250)=0,"",-SUM(H105:H250)),"") | I251: =IFERROR(IF(SUM(I105:I250)=0,"",-SUM(I105:I250)),"")

Sheet Raad
A1: =+'Invullen groen'!A4 | F1: =+'Invullen groen'!I4 | G1: =+'Invullen groen'!J4 | H1: =+'Invullen groen'!K4 | I1: =+'Invullen groen'!AW4 | J1: =+'Invullen groen'!AX4 | K1: =+'Invullen groen'!AY4 | L1: =+'Invullen groen'!AZ4 | M1: =+'Invullen groen'!BA4 | N1: =+'Invullen groen'!BB4 | O1: =+'Invullen groen'!BC4 | P1: =+'Invullen groen'!BD4
A2: Omschrijving wijziging | B2: =+'Invullen groen'!C5 | C2: =+'Invullen groen'!D5 | F2: =+'Invullen groen'!I5 | G2: =+'Invullen groen'!J5 | H2: =+'Invullen groen'!K5 | I2: =+'Invullen groen'!AW5 | J2: =+'Invullen groen'!AX5 | K2: =+'Invullen groen'!AY5 | L2: =+'Invullen groen'!AZ5 | M2: =+'Invullen groen'!BA5 | N2: =+'Invullen groen'!BB5 | O2: =+'Invullen groen'!BC5 | P2: =+'Invullen groen'!BD5
A3: =+'Invullen groen'!G4 | B3: =+'Invullen groen'!H4
A5: =+'Invullen groen'!G6 | B5: =+'Invullen groen'!H6 | F5: =+'Invullen groen'!I7 | G5: =+'Invullen groen'!J7 | H5: =+'Invullen groen'!K7 | I5: =+'Invullen groen'!AW7 | J5: =+'Invullen groen'!AX7 | K5: =+'Invullen groen'!AY7 | L5: =+'Invullen groen'!AZ7 | M5: =+'Invullen groen'!BA7 | N5: =+'Invullen groen'!BB7 | O5: =+'Invullen groen'!BC7 | P5: =+'Invullen groen'!BD7
A6: ='Invullen groen'!G7 | B6: ='Invullen groen'!H7 | F6: =+'Invullen groen'!I8 | G6: =+'Invullen groen'!J8 | H6: =+'Invullen groen'!K8 | I6: =+'Invullen groen'!AW8 | J6: =+'Invullen groen'!AX8 | K6: =+'Invullen groen'!AY8 | L6: =+'Invullen groen'!AZ8 | M6: =+'Invullen groen'!BA8 | N6: =+'Invullen groen'!BB8 | O6: =+'Invullen groen'!BC8 | P6: =+'Invullen groen'!BD8
A7: =+'Invullen groen'!A9 | B7: =+'Invullen groen'!C9 | C7: =+'Invullen groen'!G9 | D7: =+'Invullen groen'!M9 | E7: =+'Invullen groen'!H9 | F7: =+'Invullen groen'!I9 | G7: =+'Invullen groen'!J9 | H7: =+'Invullen groen'!K9 | I7: =+'Invullen groen'!AW9 | J7: =+'Invullen groen'!AX9 | K7: =+'Invullen groen'!AY9 | L7: =+'Invullen groen'!AZ9 | M7: =+'Invullen groen'!BA9 | N7: =+'Invullen groen'!BB9 | O7: =+'Invullen groen'!BC9 | P7: =+'Invullen groen'!BD9
A8: =+'Invullen groen'!A11 | D8: =+'Invullen groen'!M11 | E8: =+'Invullen groen'!H11 | F8: =+'Invullen groen'!I11 | G8: =+'Invullen groen'!J11 | H8: =+'Invullen groen'!K11 | I8: =+'Invullen groen'!AW11 | J8: =+'Invullen groen'!AX11 | K8: =+'Invullen groen'!AY11 | L8: =+'Invullen groen'!AZ11 | M8: =+'Invullen groen'!BA11 | N8: =+'Invullen groen'!BB11 | O8: =+'Invullen groen'!BC11 | P8: =+'Invullen groen'!BD11
A9: =+'Invullen groen'!A12 | B9: =+'Invullen groen'!C12 | C9: =+'Invullen groen'!G12 | D9: =+'Invullen groen'!M12 | E9: =+'Invullen groen'!H12 | F9: =+'Invullen groen'!I12 | G9: =+'Invullen groen'!J12 | H9: =+'Invullen groen'!K12 | I9: =+'Invullen groen'!AW12 | J9: =+'Invullen groen'!AX12 | K9: =+'Invullen groen'!AY12 | L9: =+'Invullen groen'!AZ12 | M9: =+'Invullen groen'!BA12 | N9: =+'Invullen groen'!BB12 | O9: =+'Invullen groen'!BC12 | P9: =+'Invullen groen'!BD12
A10: =+'Invullen groen'!A13 | B10: =+'Invullen groen'!C13 | C10: Omschrijving boekingspost | D10: =+'Invullen groen'!M13 | E10: =+'Invullen groen'!H13 | F10: =+'Invullen groen'!I13 | G10: =+'Invullen groen'!J13 | H10: =+'Invullen groen'!K13 | I10: =+'Invullen groen'!AW13 | J10: =+'Invullen groen'!AX13 | K10: =+'Invullen groen'!AY13 | L10: =+'Invullen groen'!AZ13 | M10: =+'Invullen groen'!BA13 | N10: =+'Invullen groen'!BB13 | O10: =+'Invullen groen'!BC13 | P10: =+'Invullen groen'!BD13
A11: =+'Invullen groen'!A14 | B11: =+'Invullen groen'!C14 | C11: =+'Invullen groen'!G14 | D11: =+'Invullen groen'!M14 | E11: =+'Invullen groen'!H14 | F11: =+'Invullen groen'!I14 | G11: =+'Invullen groen'!J14 | H11: =+'Invullen groen'!K14 | I11: =+'Invullen groen'!AW14 | J11: =+'Invullen groen'!AX14 | K11: =+'Invullen groen'!AY14 | L11: =+'Invullen groen'!AZ14 | M11: =+'Invullen groen'!BA14 | N11: =+'Invullen groen'!BB14 | O11: =+'Invullen groen'!BC14 | P11: =+'Invullen groen'!BD14
A12: =+'Invullen groen'!A15 | B12: =+'Invullen groen'!C15 | C12: =+'Invullen groen'!G15 | D12: =+'Invullen groen'!M15 | E12: =+'Invullen groen'!H15 | F12: =+'Invullen groen'!I15 | G12: =+'Invullen groen'!J15 | H12: =+'Invullen groen'!K15 | I12: =+'Invullen groen'!AW15 | J12: =+'Invullen groen'!AX15 | K12: =+'Invullen groen'!AY15 | L12: =+'Invullen groen'!AZ15 | M12: =+'Invullen groen'!BA15 | N12: =+'Invullen groen'!BB15 | O12: =+'Invullen groen'!BC15 | P12: =+'Invullen groen'!BD15
A13: =+'Invullen groen'!A16 | B13: =+'Invullen groen'!C16 | C13: =+'Invullen groen'!G16 | D13: =+'Invullen groen'!M16 | E13: =+'Invullen groen'!H16 | F13: =+'Invullen groen'!I16 | G13: =+'Invullen groen'!J16 | H13: =+'Invullen groen'!K16 | I13: =+'Invullen groen'!AW16 | J13: =+'Invullen groen'!AX16 | K13: =+'Invullen groen'!AY16 | L13: =+'Invullen groen'!AZ16 | M13: =+'Invullen groen'!BA16 | N13: =+'Invullen groen'!BB16 | O13: =+'Invullen groen'!BC16 | P13: =+'Invullen groen'!BD16
A14: =+'Invullen groen'!A17 | B14: =+'Invullen groen'!C17 | C14: =+'Invullen groen'!G17 | D14: =+'Invullen groen'!M17 | E14: =+'Invullen groen'!H17 | F14: =+'Invullen groen'!I17 | G14: =+'Invullen groen'!J17 | H14: =+'Invullen groen'!K17 | I14: =+'Invullen groen'!AW17 | J14: =+'Invullen groen'!AX17 | K14: =+'Invullen groen'!AY17 | L14: =+'Invullen groen'!AZ17 | M14: =+'Invullen groen'!BA17 | N14: =+'Invullen groen'!BB17 | O14: =+'Invullen groen'!BC17 | P14: =+'Invullen groen'!BD17
A15: =+'Invullen groen'!A18 | B15: =+'Invullen groen'!C18 | C15: =+'Invullen groen'!G18 | D15: =+'Invullen groen'!M18 | E15: =+'Invullen groen'!H18 | F15: =+'Invullen groen'!I18 | G15: =+'Invullen groen'!J18 | H15: =+'Invullen groen'!K18 | I15: =+'Invullen groen'!AW18 | J15: =+'Invullen groen'!AX18 | K15: =+'Invullen groen'!AY18 | L15: =+'Invullen groen'!AZ18 | M15: =+'Invullen groen'!BA18 | N15: =+'Invullen groen'!BB18 | O15: =+'Invullen groen'!BC18 | P15: =+'Invullen groen'!BD18
A16: =+'Invullen groen'!A19 | B16: =+'Invullen groen'!C19 | C16: =+'Invullen groen'!G19 | D16: =+'Invullen groen'!M19 | E16: =+'Invullen groen'!H19 | F16: =+'Invullen groen'!I19 | G16: =+'Invullen groen'!J19 | H16: =+'Invullen groen'!K19 | I16: =+'Invullen groen'!AW19 | J16: =+'Invullen groen'!AX19 | K16: =+'Invullen groen'!AY19 | L16: =+'Invullen groen'!AZ19 | M16: =+'Invullen groen'!BA19 | N16: =+'Invullen groen'!BB19 | O16: =+'Invullen groen'!BC19 | P16: =+'Invullen groen'!BD19
A17: =+'Invullen groen'!A20 | B17: =+'Invullen groen'!C20 | C17: =+'Invullen groen'!G20 | D17: =+'Invullen groen'!M20 | E17: =+'Invullen groen'!H20 | F17: =+'Invullen groen'!I20 | G17: =+'Invullen groen'!J20 | H17: =+'Invullen groen'!K20 | I17: =+'Invullen groen'!AW20 | J17: =+'Invullen groen'!AX20 | K17: =+'Invullen groen'!AY20 | L17: =+'Invullen groen'!AZ20 | M17: =+'Invullen groen'!BA20 | N17: =+'Invullen groen'!BB20 | O17: =+'Invullen groen'!BC20 | P17: =+'Invullen groen'!BD20
A18: =+'Invullen groen'!A21 | B18: =+'Invullen groen'!C21 | C18: =+'Invullen groen'!G21 | D18: =+'Invullen groen'!M21 | E18: =+'Invullen groen'!H21 | F18: =+'Invullen groen'!I21 | G18: =+'Invullen groen'!J21 | H18: =+'Invullen groen'!K21 | I18: =+'Invullen groen'!AW21 | J18: =+'Invullen groen'!AX21 | K18: =+'Invullen groen'!AY21 | L18: =+'Invullen groen'!AZ21 | M18: =+'Invullen groen'!BA21 | N18: =+'Invullen groen'!BB21 | O18: =+'Invullen groen'!BC21 | P18: =+'Invullen groen'!BD21
A19: =+'Invullen groen'!A22 | B19: =+'Invullen groen'!C22 | C19: =+'Invullen groen'!G22 | D19: =+'Invullen groen'!M22 | E19: =+'Invullen groen'!H22 | F19: =+'Invullen groen'!I22 | G19: =+'Invullen groen'!J22 | H19: =+'Invullen groen'!K22 | I19: =+'Invullen groen'!AW22 | J19: =+'Invullen groen'!AX22 | K19: =+'Invullen groen'!AY22 | L19: =+'Invullen groen'!AZ22 | M19: =+'Invullen groen'!BA22 | N19: =+'Invullen groen'!BB22 | O19: =+'Invullen groen'!BC22 | P19: =+'Invullen groen'!BD22
A20: =+'Invullen groen'!A23 | B20: =+'Invullen groen'!C23 | C20: =+'Invullen groen'!G23 | D20: =+'Invullen groen'!M23 | E20: =+'Invullen groen'!H23 | F20: =+'Invullen groen'!I23 | G20: =+'Invullen groen'!J23 | H20: =+'Invullen groen'!K23 | I20: =+'Invullen groen'!AW23 | J20: =+'Invullen groen'!AX23 | K20: =+'Invullen groen'!AY23 | L20: =+'Invullen groen'!AZ23 | M20: =+'Invullen groen'!BA23 | N20: =+'Invullen groen'!BB23 | O20: =+'Invullen groen'!BC23 | P20: =+'Invullen groen'!BD23
A21: =+'Invullen groen'!A24 | B21: =+'Invullen groen'!C24 | C21: =+'Invullen groen'!G24 | D21: =+'Invullen groen'!M24 | E21: =+'Invullen groen'!H24 | F21: =+'Invullen groen'!I24 | G21: =+'Invullen groen'!J24 | H21: =+'Invullen groen'!K24 | I21: =+'Invullen groen'!AW24 | J21: =+'Invullen groen'!AX24 | K21: =+'Invullen groen'!AY24 | L21: =+'Invullen groen'!AZ24 | M21: =+'Invullen groen'!BA24 | N21: =+'Invullen groen'!BB24 | O21: =+'Invullen groen'!BC24 | P21: =+'Invullen groen'!BD24
A22: =+'Invullen groen'!A25 | B22: =+'Invullen groen'!C25 | C22: =+'Invullen groen'!G25 | D22: =+'Invullen groen'!M25 | E22: =+'Invullen groen'!H25 | F22: =+'Invullen groen'!I25 | G22: =+'Invullen groen'!J25 | H22: =+'Invullen groen'!K25 | I22: =+'Invullen groen'!AW25 | J22: =+'Invullen groen'!AX25 | K22: =+'Invullen groen'!AY25 | L22: =+'Invullen groen'!AZ25 | M22: =+'Invullen groen'!BA25 | N22: =+'Invullen groen'!BB25 | O22: =+'Invullen groen'!BC25 | P22: =+'Invullen groen'!BD25
